<?xml version="1.0" encoding="UTF-8"?>
<!-- Generated by org.testng.reporters.JUnitReportReporter -->
<testsuite skipped="2" hostname="Dhruba" name="testng.AssertionsTest" tests="6" failures="1" timestamp="05 Jan 2019 07:08:22 GMT" time="0.030" errors="0">
  <testcase name="test7" time="0.000" classname="testng.AssertionsTest">
    <skipped/>
  </testcase> <!-- test7 -->
  <testcase name="test6" time="0.005" classname="testng.AssertionsTest">
    <failure type="java.lang.AssertionError" message="expected [hello] but found [Test]">
      <![CDATA[java.lang.AssertionError: expected [hello] but found [Test]
	at org.testng.Assert.fail(Assert.java:93)
	at org.testng.Assert.failNotEquals(Assert.java:512)
	at org.testng.Assert.assertEqualsImpl(Assert.java:134)
	at org.testng.Assert.assertEquals(Assert.java:115)
	at org.testng.Assert.assertEquals(Assert.java:189)
	at org.testng.Assert.assertEquals(Assert.java:199)
	at testng.AssertionsTest.test6(AssertionsTest.java:25)
	at sun.reflect.NativeMethodAccessorImpl.invoke0(Native Method)
	at sun.reflect.NativeMethodAccessorImpl.invoke(Unknown Source)
	at sun.reflect.DelegatingMethodAccessorImpl.invoke(Unknown Source)
	at java.lang.reflect.Method.invoke(Unknown Source)
	at org.testng.internal.MethodInvocationHelper.invokeMethod(MethodInvocationHelper.java:108)
	at org.testng.internal.Invoker.invokeMethod(Invoker.java:661)
	at org.testng.internal.Invoker.invokeTestMethod(Invoker.java:869)
	at org.testng.internal.Invoker.invokeTestMethods(Invoker.java:1193)
	at org.testng.internal.TestMethodWorker.invokeTestMethods(TestMethodWorker.java:126)
	at org.testng.internal.TestMethodWorker.run(TestMethodWorker.java:109)
	at org.testng.TestRunner.privateRun(TestRunner.java:744)
	at org.testng.TestRunner.run(TestRunner.java:602)
	at org.testng.SuiteRunner.runTest(SuiteRunner.java:380)
	at org.testng.SuiteRunner.runSequentially(SuiteRunner.java:375)
	at org.testng.SuiteRunner.privateRun(SuiteRunner.java:340)
	at org.testng.SuiteRunner.run(SuiteRunner.java:289)
	at org.testng.SuiteRunnerWorker.runSuite(SuiteRunnerWorker.java:52)
	at org.testng.SuiteRunnerWorker.run(SuiteRunnerWorker.java:86)
	at org.testng.TestNG.runSuitesSequentially(TestNG.java:1301)
	at org.testng.TestNG.runSuitesLocally(TestNG.java:1226)
	at org.testng.TestNG.runSuites(TestNG.java:1144)
	at org.testng.TestNG.run(TestNG.java:1115)
	at org.testng.remote.AbstractRemoteTestNG.run(AbstractRemoteTestNG.java:114)
	at org.testng.remote.RemoteTestNG.initAndRun(RemoteTestNG.java:251)
	at org.testng.remote.RemoteTestNG.main(RemoteTestNG.java:77)
]]>
    </failure>
  </testcase> <!-- test6 -->
  <testcase name="test4" time="0.003" classname="testng.AssertionsTest"/>
  <testcase name="test9" time="0.000" classname="testng.AssertionsTest">
    <skipped/>
  </testcase> <!-- test9 -->
  <testcase name="test5" time="0.003" classname="testng.AssertionsTest"/>
  <testcase name="test1" time="0.019" classname="testng.AssertionsTest"/>
</testsuite> <!-- testng.AssertionsTest -->
